<?xml version="1.0" ?>
<robot name="yujin-Kobuki" xmlns:xacro="http://ros.org/wiki/xacro">

  <xacro:include filename="$(find robots_description)/model/chassis/yujin/urdf/yujin-Kobuki_gazebo.urdf.xacro"/>
 
  <xacro:property name="M_SCALE" value="0.001"/>
  <xacro:property name="M_PI" value="3.1415926535897931"/> 

  <!-- Kobuki --> 
  <xacro:macro name="yujin-Kobuki">   
    <link name="base_footprint"/>
    <joint name="base_link_joint" type="fixed">
      <origin xyz="0 0 0.0102" rpy="0 0 0" />
      <parent link="base_footprint"/>
      <child link="base_link" />
    </joint>
    <link name="base_link">
      <visual>
        <geometry>
          <mesh filename="package://robots_description/model/chassis/yujin/meshes/main_body.dae" />
        </geometry>
        <origin xyz="0.001 0 0.05199" rpy="0 0 0"/>
      </visual>
      <collision>
        <geometry>
          <cylinder length="0.10938" radius="0.176"/>
        </geometry>
        <origin xyz="0.0 0 0.05949" rpy="0 0 0"/>
      </collision>
      <inertial>
        <mass value="2.4"/> <!-- 2.4/2.6 kg for small/big battery pack -->
        <origin xyz="0 0 0"/>
        <inertia ixx="0.0001" ixy="0.0" ixz="0.0"
                 iyy="0.0001" iyz="0.0" 
                 izz="0.0001" />
      </inertial>
    </link>
    
    <joint name="wheel_left_link_joint" type="continuous">
      <origin xyz="0.00 ${0.23/2} 0.0250" rpy="${-M_PI/2} 0 0"/>
      <parent link="base_link"/>
      <child link="wheel_left_link"/>
      <axis xyz="0 0 1"/>
    </joint>
    <link name="wheel_left_link">
      <visual>
        <geometry>
          <mesh filename="package://robots_description/model/chassis/yujin/meshes/wheel.dae"/>
        </geometry>
        <origin xyz="0 0 0" rpy="0 0 0"/>
      </visual>
      <collision>
        <geometry>
          <cylinder length="0.0206" radius="0.0352"/>
        </geometry>
        <origin rpy="0 0 0" xyz="0 0 0"/>
      </collision>
      <inertial>
        <mass value="0.01" />
        <origin xyz="0 0 0" />        
        <inertia ixx="0.001" ixy="0.0" ixz="0.0"
                 iyy="0.001" iyz="0.0" 
                 izz="0.001" />
      </inertial>
    </link>
    
    <joint name="wheel_right_link_joint" type="continuous">
      <origin xyz="0.00 -${0.23/2} 0.0250" rpy="${-M_PI/2} 0 0"/>
      <parent link="base_link"/>
      <child link="wheel_right_link"/>
      <axis xyz="0 0 1"/>
    </joint>
    <link name="wheel_right_link">
      <visual>
        <geometry>
          <mesh filename="package://robots_description/model/chassis/yujin/meshes/wheel.dae"/>
        </geometry>
        <origin xyz="0 0 0" rpy="0 0 0"/>
      </visual>
      <collision>
        <geometry>
          <cylinder length="0.0206" radius="0.0350"/>
        </geometry>
        <origin rpy="0 0 0" xyz="0 0 0"/>
      </collision>
      <inertial>
        <mass value="0.01" />
        <origin xyz="0 0 0" />        
        <inertia ixx="0.001" ixy="0.0" ixz="0.0"
                 iyy="0.001" iyz="0.0" 
                 izz="0.001" />
      </inertial>
    </link>
    
    <joint name="caster_front_link_joint" type="fixed">
      <origin xyz="0.115 0.0 0.007" rpy="${-M_PI/2} 0 0"/>
      <parent link="base_link"/>
      <child link="caster_front_link"/>
    </joint>
    <link name="caster_front_link">
      <collision>
        <geometry>
          <cylinder length="0.0176" radius="0.017"/>
        </geometry>
        <origin rpy="0 0 0" xyz="0 0 0"/>
      </collision>      
      <inertial>
        <mass value="0.01" />
        <origin xyz="0 0 0" />
        <inertia ixx="0.001" ixy="0.0" ixz="0.0"
                 iyy="0.001" iyz="0.0" 
                 izz="0.001" />
      </inertial>
    </link>
    
    <joint name="caster_back_link_joint" type="fixed">
      <origin xyz="-0.135 0.0 0.009" rpy="${-M_PI/2} 0 0"/>
      <parent link="base_link"/>
      <child link="caster_back_link"/>
    </joint>
    <link name="caster_back_link">
      <collision>
        <geometry>
          <cylinder length="0.0176" radius="0.017"/>
        </geometry>
        <origin rpy="0 0 0" xyz="0 0 0"/>
      </collision>      
      <inertial>
        <mass value="0.01" />
        <origin xyz="0 0 0" />        
        <inertia ixx="0.001" ixy="0.0" ixz="0.0"
                 iyy="0.001" iyz="0.0" 
                 izz="0.001" />
      </inertial>
    </link>
    
    <!-- Kobuki's sensors -->
    <joint name="gyro_link_joint" type="fixed">
      <origin xyz="0.056 0.062 0.0202" rpy="0 0 0"/>
      <parent link="base_link"/>
      <child link="gyro_link"/>
      <axis xyz="0 1 0"/>
    </joint>
    <link name="gyro_link">
      <inertial>
        <mass value="0.001"/>
        <origin xyz="0 0 0" rpy="0 0 0"/>
        <inertia ixx="0.0001" ixy="0" ixz="0" 
                 iyy="0.000001" iyz="0"
                 izz="0.0001"/>
      </inertial>
    </link>
	
	  <joint name="cliff_sensor_left_link_joint" type="fixed">
	    <origin xyz="0.08734 0.13601 0.0214" rpy="0 ${M_PI/2} 0" />
	    <parent link="base_link"/>
	    <child link="cliff_sensor_left_link" />
	  </joint>
	  <link name="cliff_sensor_left_link">
      <inertial>
        <mass value="0.0001" />
        <origin xyz="0 0 0" />
        <inertia ixx="0.0001" ixy="0.0" ixz="0.0"
                 iyy="0.0001" iyz="0.0" 
                 izz="0.0001" />
      </inertial>
    </link>
	
	  <joint name="cliff_sensor_right_link_joint" type="fixed">
	    <origin xyz="0.085 -0.13601 0.0214" rpy="0 ${M_PI/2} 0" />
	    <parent link="base_link"/>
	    <child link="cliff_sensor_right_link" />
	  </joint>
    <link name="cliff_sensor_right_link">
      <inertial>
        <mass value="0.0001" />
        <origin xyz="0 0 0" />
        <inertia ixx="0.0001" ixy="0.0" ixz="0.0"
                 iyy="0.0001" iyz="0.0" 
                 izz="0.0001" />
      </inertial>
    </link>
    
    <joint name="cliff_sensor_front_link_joint" type="fixed">
      <origin xyz="0.156 0.00 0.0214" rpy="0 ${M_PI/2} 0" />
      <parent link="base_link"/>
      <child link="cliff_sensor_front_link" />
    </joint>
    <link name="cliff_sensor_front_link">
      <inertial>
        <mass value="0.0001" />
        <origin xyz="0 0 0" />
        <inertia ixx="0.0001" ixy="0.0" ixz="0.0"
                 iyy="0.0001" iyz="0.0" 
                 izz="0.0001" />
      </inertial>
    </link>
  </xacro:macro>
 
  <xacro:macro name="yujin-Kobuki_gazebo">
    <kobuki_controller/>
    <kobuki_bumpers/>
    <kobuki_cliff_sensors/>
    <kobuki_imu/>
  </xacro:macro>

  <xacro:macro name="yujin-kobuki">  
    <yujin-Kobuki/> 
    <yujin-Kobuki_gazebo/>
  </xacro:macro>
</robot>